# 프로미스(1)

## 비동기 처리를 위한 콜백 패턴의 단점

### 콜백 헬

```JavaScript
// GET 요청을 위한 비동기 함수
const get = url => {
  const xhr = new XMLHttpRequest();
  xhr.open('GET', url);
  xhr.send();

  xhr.onload = () => {
    if(xhr.status === 200){
      // 서버 응답 반환
      return JSON.parse(xhr.response);
    } else {
      console.error(`${xhr.status} ${xhr.statusText}`);
    }
  };
};

const response = get('https://jsonplaceholder.typicode.com/posts/1');
console.log(response); // undefined
```

**비동기 함수를 호출하면 함수 내부의 비동기로 동작하는 코드가 완료되지 않았다 해도 기다리지 않고 즉시 종료된다.** <br>
**즉 비동기 함수 내부의 비동기로 동작하는 코드는 비동기 함수가 종료된 이후에 완료된다.**

get 함수는 비동기 함수이다 이유는 get함수 내부의 **onload 이벤트 핸들러가 비동기로 동작**하기 때문

> **콜백 헬(callback hell)**이란 콜백 함수를 통해 비동기 처리 결과에 대한 후속 처리를 수행하는 비동기 함수가 비동기 처리 결과를 가지고 또 다시 비동기 함수를 호출해야 한다면 콜백 함수 호출이 중첩되어 복잡도가 높아지고 가독성이 나빠지는 현상

```JavaScript
// 콜백 헬이 발생하는 전형적인 사례
get("/step1", (a) => {
  get(`/step2/${a}`, (b) => {
    get(`/step3/${b}`, (c) => {
      get(`/step4/${c}`, (d) => {
        console.log(d);
      });
    });
  });
});
```

### 에러 처리의 한계

비동기 처리를 위한 콜백 패턴의 문제점 중에 가장 심각한 것은 에러처리가 곤란하다는 것이다

```JavaScript
try {
  setTimeout(() => { throw new Error('Error!'); }, 1000);
} catch (e) {
  // 에러를 캐치하지 못함
  console.error('에러', e);
}`
```

#### 에러를 캐치하지 못하는 이유는??

위 예제 코드가 다음과 같은 순서로 동작하기 때문이다

- `try-catch`문이 실행되어 `call stack`에 push된다
- `setTimeout`이 실행되어 콜백 함수가 `event loop`에 등록 된다
- `try-catch`문에서 에러가 발생하지 않았고 다음 코드도 없기때문에 실행 종료되어 `call stack`에서 pop된다
- `setTimeout`의 콜백 함수가 `event loop`에 등록된지 1초 뒤에 `task queue`로 push된다
- `call stack`에 실행중인 컨텍스트가 없으므로 콜백 함수는 `event loop`에 의해서 `call stack`으로 이동되고 실행된다
- 콜백 함수가 에러를 발생시킨다
- 에러를 캐치할 실행 중인 실행 컨텍스트의 상위 컨텍스트가 없기 때문에 에러를 캐치하지 못하고 종료

**에러는 호출자(caller) 방향으로 전파된다.** 즉 콜 스택의 아래방향(실행 중인 실행 컨텍스트가 푸시되기 직전에 푸시된 상위 실행 컨텍스트 방향)으로 전파된다. 하지만 setTimeout 함수의 콜백함수를 호출한 것은 setTimeout 함수가 아니기 때문에 catch에서 에러를 캐치하지 못한다.

이를 극복하기 위해 ES6에서 **프로미스(Promise)가 도입**되었다.

## 프로미스의 생성

콜백 함수에서 에러를 처리하기 어렵다는 문제를 극복하기 위해 ES6에서 `Promise`가 도입되었다. `Promise` 생성자 함수를 new 연산자와 함께 호출하면 `Promise`객체를 생성한다. `Promise` 생성자 함수는 비동기 처리를 수행할 콜백 함수에 resolve와 reject 함수를 인수로 전달 받는다.

```JavaScript
// 프로미스 생성
const promise = new Promise((resolve, reject) => {
  // Promise 함수의 콜백 함수 내부에서 비동기 처리를 수행한다.
  if (/* 비동기 처리 성공 */) {
    resolve('result');
  } else { /* 비동기 처리 실패 */
    reject('failure reason');
  }
});
```

`Promise` 생성자 함수가 인수로 전달받은 콜백 함수의 내부에서 비동기 처리를 수행하는 것이다. 이때, 비동기 처리가 성공하면 `resolve` 함수를 호출하고, 실패하면 `reject` 함수를 호출한다.

```JavaScript
// GET 요청을 위한 비동기 함수
const promiseGet = (url) => {
  return new Promise((resolve, reject) => {
    const xhr = new XMLHttpRequest();
    xhr.open("GET", url);
    xhr.send();

    xhr.onload = () => {
      if (xhr.status === 200) {
        // 성공적으로 응답을 전달받으면 resolve 함수를 호출한다.
        resolve(JSON.parse(xhr.response));
      } else {
        // 에러 처리를 위해 reject 함수를 호출한다.
        reject(new Error(xhr.status));
      }
    };
  });
};

// promiseGet 함수는 프로미스를 반환한다.
promiseGet("https://jsonplaceholder.typicode.com/posts/1");
```

만약 비동기 처리가 성공하면 비동기 처리 결과를 `resolve` 함수에 인수로 전달하며 호출하고, 실패하면 에러를 `reject` 함수에 인수로 전달하면서 호출한다

**프로미스가 갖는 상태(state) 정보**
|프로미스의 상태 정보|의미|상태 변경 조건|
|------------------|----|-------------|
|pending|비동기 처리가 아직 수행되지 않은 상태|프로미스가 생성된 직후 상태|
|fulfilled|비동기 처리 수행되고 결과가 성공인 상태|resolve 함수 호출|
|rejected|비동기 처리 수행되고 결과가 실패인 상태|reject 함수 호출|

이때, 비동기 처리가 완료된 상태인 fulfilled 상태와 rejected 상태를 **settled 상태**라고 한다. 한 번 pending 상태에서 settled 상태가 되면 다시 pending 상태로 되돌릴 수는 없다. 또 Promise 객체는 처리 상태와 함께 결과 값인 result를 상태로 갖는다

**프로미스는 비동기 처리 상태와 처리 결과를 관리하는 객체이다**

## 프로미스의 후속 처리 메서드

프로미스의 비동기 처리 상태가 변화하면 후속 처리 메서드에 인수로 전달한 콜백 함수가 선택적으로 호출된다. 이때 후속 처리 메서드의 콜백 함수에 프로미스의 처리 결과가 인수로 전달된다.

### Promise.prototype.then

**then 메서드**는 두 개의 콜백 함수를 인수로 전달받는다

- 첫 번째 콜백함수: 프로미스가 fulfilled 상태가 되면 호출되는 성공 처리 콜백 함수
- 두 번째 콜백함수: 프로미스가 rejected 상태가 되면 호출되는 실패 처리 콜백 함수

```JavaScript
// fulfilled
new Promise(resolve => resolve('fulfilled'))
.then(v => console.log(v), e=> console.log(e)); //fulfilled

// rejected
new Promise((\_, reject) => reject(new Error('rejected')))
.then(v => console.log(v), e => console.error(e)); // Error : rejected
```

### Promise.prototype.catch

**catch 메서드**는 한 개의 콜백 함수를 인수로 전달받음. catch 메서드의 콜백 함수는 프로미스가 rejected 상태인 경우만 호출된다.

```JavaScript
new Promise((\_, reject) => reject(new Error('rejected')))
.catch(e => console.log(e)); // Error : rejected
```

**catch 메서드**는 then과 동일하게 동작한다. 따라서 tehn 메서드와 마찬가지로 언제나 프로미스를 반환한다.

### Promise.prototype.finally

**finally 메서드**는 한 개의 콜백 함수를 인수로 전달받는다. 성공, 실패 상관없이 무조건 한 번 호출된다. finally 메서드도 then/catch와 동일하게 언제나 프로미스를 반환한다.

```JavaScript
new Promise(() => {})
.finally(() => console.log('finally')); // finally
```

## 프로미스의 에러 처리

프로미스의 에러처리는 후속 처리 메서드인 then, catch, finally를 사용한다

### then 메서드

then 메서드의 두번째 콜백 함수로 처리할 수 있다

```JavaScript
const wrongUrl = 'Url';

promiseGet(wrongUrl).then(
  res => console.log(res),
  err => console.log(err)
  ); // Error : 404
```

### catch 메서드

```JavaScript
const wrongUrl = 'Url';

promiseGet(wrongUrl)
  .then(res => console.log(res))
  .catch(err => console.error(err)); // Error : 404
```

catch 메서드를 호출하면 내부적으로 then(undefined, onRejected)을 호출한다.<br>
catch 메서드를 모든 then 메서드를 호출한 이후에 호출하면 비동기 처리에서 발생한 에러(rejected 상태) 뿐만 아니라 then 메서드 내부에서 발생한 에러까지 모두 캐치할 수 있다.<br>
따라서 **에러 처리는 catch 메서드를 사용하는 것이 가독성이 좋고 명확하다.**
