# 에러 처리

## 에러 처리의 필요성

에러가 발생하지 않는 코드를 작성하는 것은 불가능하다. 발생한 에러에 대해 대처하지 않고 방지하면 프로그램은 강제 종료!!

## try...catch...finally 문

```javascript
try {
  // 실행할 코드(에러가 발생할 가능성이 있는 코드)
  foo();
} catch (err) {
  // try 코드 블록에서 에러 발생 시 코드 실행됨.
  // err 에는 try 코드 블록에서 발생한 Error 객체가 전달됨.
  console.error(err);
} finally {
  // 에러 발생과 상관 없이 반드시 한 번 실행됨.
  console.log("finally");
}
```

## Error 객체

Error 생성자 함수에는 에러를 상세히 설명하는 에러 메세지를 인수로 전달할 수 있다

```JavaScript
const error = new Error("invalid");
```

Error 생성자 함수가 생성한 에러 객체는 message 프로퍼티와 stack 프로퍼티를 갖는다

- message 프로퍼티의 값 : Error 생성자 함수에 인수로 전달한 에러 메세지
- stack 프로퍼티 값 : 에러를 발생시킨 콜스택의 호출 정보를 나타내는 문자열이며 디버깅 목적으로 사용

SyntaxError, ReferenceError, TypeError, RangeError, URIError, EvalError 생성자 함수가 생성한 에러 객체의 프로토타입은 모두 Error.prototype을 상속받는다

```JavaScript
1 @ 1; // SyntaxError : Invalid or unexpected token
foo(); // RefrenceError : foo is not defined
null.foo; // TypeError : Cannot read property 'foo' of null
new Array(-1); // RangeError : Invalid array length
decodeURIComponent('%'); // URIError : URI malformed
```

## throw 문

Error 생성자 함수로 에러 객체를 생성한다고 에러가 발생하는 것은 아니다. 즉, 에러 객체 생성과 에러 발생은 의미가 다르다

에러를 발생시키려면 try 코드 블룩에서 throw 문으로 에러 객체를 던져야 한다.

```JavaScript
try {
  // 에러 객체를 던지면 catch 코드 블록 실행됨.
  throw new Error('something wrong');
} catch (error) {
  console.log(error);
}
```

## 에러의 전파

에러는 호출자 방향으로 전파된다. 즉, 콜 스택의 아래 방향으로 전파된다.

```javascript
const foo = () => {
  throw new Error("foo에서 발생한 에러");
};

const bar = () => {
  foo();
};

const baz = () => {
  bar();
};

try {
  baz();
} catch (err) {
  console.error(err);
}
```

baz 함수를 호출하면 bar 함수가 호출되고 foo 함수가 호출되고 foo 함수에서 에러를 throw한다.

이때 foo 함수가 throw한 에러는 호출자에게 전파되어 전역에서 캐치된다.

throw된 에러를 캐치하지 않으면 호출자 방향으로 전파된다.<br>
이때 throw된 에러를 캐치하여 적절히 대응하면 실행 흐름을 복구할 수 있지만 캐치하지 않으면 프로그램은 강제 종료된다.
